Workbook

Sheet Members
A1: Member | B1: Join date | C1: Renewal date | D1: Status | E1: Last active in Skool (days ago) | F1: Last contact (auto) | G1: Days since contact | H1: Current goal | I1: Next action | J1: Notes | K1: Last active date (auto, used by nightly sync) | L1: member_id | M1: channel | N1: profile_link | O1: plan_value | P1: opted_out | Q1: skip | R1: email | S1: posts | T1: intro_posted
A2: Owen Fontaine | B2: 45940 | C2: =IF(B2="","",EDATE(B2,12*(DATEDIF(B2,TODAY(),"y")+1))) | D2: =IF(AND(K2="",F2=""),"",IF(OR(AND(K2<>"",TODAY()-K2>=14),AND(F2<>"",TODAY()-F2>=21)),"Red",IF(OR(AND(K2<>"",TODAY()-K2>=7),AND(C2<>"",C2-TODAY()<=30)),"Yellow","Green"))) | E2: =IF(K2="","",TODAY()-K2) | F2: =IFERROR(1/(1/MAXIFS(Touchpoints!$A:$A,Touchpoints!$B:$B,A2)),"") | G2: =IF(F2="","",TODAY()-F2) | H2: move from freelance to a full-time role | K2: 46253 | L2: M-0001 | M2: none | R2: owen.fontaine@example.com | S2: 29 | T2: yes
A3: Tomas Grimshaw | B3: 45580 | C3: =IF(B3="","",EDATE(B3,12*(DATEDIF(B3,TODAY(),"y")+1))) | D3: =IF(AND(K3="",F3=""),"",IF(OR(AND(K3<>"",TODAY()-K3>=14),AND(F3<>"",TODAY()-F3>=21)),"Red",IF(OR(AND(K3<>"",TODAY()-K3>=7),AND(C3<>"",C3-TODAY()<=30)),"Yellow","Green"))) | E3: =IF(K3="","",TODAY()-K3) | F3: =IFERROR(1/(1/MAXIFS(Touchpoints!$A:$A,Touchpoints!$B:$B,A3)),"") | G3: =IF(F3="","",TODAY()-F3) | K3: 46024 | L3: M-0002 | M3: none | R3: tomas.grimshaw@example.com | S3: 36 | T3: yes
A4: Terrence Vanderbilt | B4: 45948 | C4: =IF(B4="","",EDATE(B4,12*(DATEDIF(B4,TODAY(),"y")+1))) | D4: =IF(AND(K4="",F4=""),"",IF(OR(AND(K4<>"",TODAY()-K4>=14),AND(F4<>"",TODAY()-F4>=21)),"Red",IF(OR(AND(K4<>"",TODAY()-K4>=7),AND(C4<>"",C4-TODAY()<=30)),"Yellow","Green"))) | E4: =IF(K4="","",TODAY()-K4) | F4: =IFERROR(1/(1/MAXIFS(Touchpoints!$A:$A,Touchpoints!$B:$B,A4)),"") | G4: =IF(F4="","",TODAY()-F4) | K4: 46301 | L4: M-0003 | M4: none | R4: terrence.vanderbilt@example.com | S4: 30 | T4: yes
A5: Niklas Voss | B5: 45950 | C5: =IF(B5="","",EDATE(B5,12*(DATEDIF(B5,TODAY(),"y")+1))) | D5: =IF(AND(K5="",F5=""),"",IF(OR(AND(K5<>"",TODAY()-K5>=14),AND(F5<>"",TODAY()-F5>=21)),"Red",IF(OR(AND(K5<>"",TODAY()-K5>=7),AND(C5<>"",C5-TODAY()<=30)),"Yellow","Green"))) | E5: =IF(K5="","",TODAY()-K5) | F5: =IFERROR(1/(1/MAXIFS(Touchpoints!$A:$A,Touchpoints!$B:$B,A5)),"") | G5: =IF(F5="","",TODAY()-F5) | K5: 46304 | L5: M-0004 | M5: none | R5: niklas.voss@example.com | S5: 29 | T5: yes
A6: Quentin Wycliffe | B6: 45591 | C6: =IF(B6="","",EDATE(B6,12*(DATEDIF(B6,TODAY(),"y")+1))) | D6: =IF(AND(K6="",F6=""),"",IF(OR(AND(K6<>"",TODAY()-K6>=14),AND(F6<>"",TODAY()-F6>=21)),"Red",IF(OR(AND(K6<>"",TODAY()-K6>=7),AND(C6<>"",C6-TODAY()<=30)),"Yellow","Green"))) | E6: =IF(K6="","",TODAY()-K6) | F6: =IFERROR(1/(1/MAXIFS(Touchpoints!$A:$A,Touchpoints!$B:$B,A6)),"") | G6: =IF(F6="","",TODAY()-F6) | K6: 46281 | L6: M-0005 | M6: none | R6: quentin.wycliffe@example.com | S6: 33 | T6: yes
A7: Vernon Bramwell | B7: 45957 | C7: =IF(B7="","",EDATE(B7,12*(DATEDIF(B7,TODAY(),"y")+1))) | D7: =IF(AND(K7="",F7=""),"",IF(OR(AND(K7<>"",TODAY()-K7>=14),AND(F7<>"",TODAY()-F7>=21)),"Red",IF(OR(AND(K7<>"",TODAY()-K7>=7),AND(C7<>"",C7-TODAY()<=30)),"Yellow","Green"))) | E7: =IF(K7="","",TODAY()-K7) | F7: =IFERROR(1/(1/MAXIFS(Touchpoints!$A:$A,Touchpoints!$B:$B,A7)),"") | G7: =IF(F7="","",TODAY()-F7) | K7: 46306 | L7: M-0006 | M7: none | R7: vernon.bramwell@example.com | S7: 38 | T7: yes
A8: Basil Whitfield | B8: 45959 | C8: =IF(B8="","",EDATE(B8,12*(DATEDIF(B8,TODAY(),"y")+1))) | D8: =IF(AND(K8="",F8=""),"",IF(OR(AND(K8<>"",TODAY()-K8>=14),AND(F8<>"",TODAY()-F8>=21)),"Red",IF(OR(AND(K8<>"",TODAY()-K8>=7),AND(C8<>"",C8-TODAY()<=30)),"Yellow","Green"))) | E8: =IF(K8="","",TODAY()-K8) | F8: =IFERROR(1/(1/MAXIFS(Touchpoints!$A:$A,Touchpoints!$B:$B,A8)),"") | G8: =IF(F8="","",TODAY()-F8) | K8: 46064 | L8: M-0007 | M8: none | R8: basil.whitfield@example.com | S8: 13 | T8: yes
A9: Xavier Yates | B9: 45603 | C9: =IF(B9="","",EDATE(B9,12*(DATEDIF(B9,TODAY(),"y")+1))) | D9: =IF(AND(K9="",F9=""),"",IF(OR(AND(K9<>"",TODAY()-K9>=14),AND(F9<>"",TODAY()-F9>=21)),"Red",IF(OR(AND(K9<>"",TODAY()-K9>=7),AND(C9<>"",C9-TODAY()<=30)),"Yellow","Green"))) | E9: =IF(K9="","",TODAY()-K9) | F9: =IFERROR(1/(1/MAXIFS(Touchpoints!$A:$A,Touchpoints!$B:$B,A9)),"") | G9: =IF(F9="","",TODAY()-F9) | K9: 46311 | L9: M-0008 | M9: none | R9: xavier.yates@example.com | S9: 12 | T9: yes
A10: Franklin Hawthorne | B10: 45986 | C10: =IF(B10="","",EDATE(B10,12*(DATEDIF(B10,TODAY(),"y")+1))) | D10: =IF(AND(K10="",F10=""),"",IF(OR(AND(K10<>"",TODAY()-K10>=14),AND(F10<>"",TODAY()-F10>=21)),"Red",IF(OR(AND(K10<>"",TODAY()-K10>=7),AND(C10<>"",C10-TODAY()<=30)),"Yellow","Green"))) | E10: =IF(K10="","",TODAY()-K10) | F10: =IFERROR(1/(1/MAXIFS(Touchpoints!$A:$A,Touchpoints!$B:$B,A10)),"") | G10: =IF(F10="","",TODAY()-F10) | H10: record 10 podcast episodes | J10: Moderator | K10: 46159 | L10: M-0009 | M10: none | R10: franklin.hawthorne@example.com | S10: 33 | T10: yes
A11: Gavin Mumford | B11: 45989 | C11: =IF(B11="","",EDATE(B11,12*(DATEDIF(B11,TODAY(),"y")+1))) | D11: =IF(AND(K11="",F11=""),"",IF(OR(AND(K11<>"",TODAY()-K11>=14),AND(F11<>"",TODAY()-F11>=21)),"Red",IF(OR(AND(K11<>"",TODAY()-K11>=7),AND(C11<>"",C11-TODAY()<=30)),"Yellow","Green"))) | E11: =IF(K11="","",TODAY()-K11) | F11: =IFERROR(1/(1/MAXIFS(Touchpoints!$A:$A,Touchpoints!$B:$B,A11)),"") | G11: =IF(F11="","",TODAY()-F11) | K11: 46255 | L11: M-0010 | M11: none | R11: gavin.mumford@example.com | S11: 31 | T11: yes
A12: Luigi Northgate | B12: 45650 | C12: =IF(B12="","",EDATE(B12,12*(DATEDIF(B12,TODAY(),"y")+1))) | D12: =IF(AND(K12="",F12=""),"",IF(OR(AND(K12<>"",TODAY()-K12>=14),AND(F12<>"",TODAY()-F12>=21)),"Red",IF(OR(AND(K12<>"",TODAY()-K12>=7),AND(C12<>"",C12-TODAY()<=30)),"Yellow","Green"))) | E12: =IF(K12="","",TODAY()-K12) | F12: =IFERROR(1/(1/MAXIFS(Touchpoints!$A:$A,Touchpoints!$B:$B,A12)),"") | G12: =IF(F12="","",TODAY()-F12) | K12: 46311 | L12: M-0011 | M12: none | R12: luigi.northgate@example.com | S12: 40 | T12: yes
A13: Peter Sanderson | B13: 46016 | C13: =IF(B13="","",EDATE(B13,12*(DATEDIF(B13,TODAY(),"y")+1))) | D13: =IF(AND(K13="",F13=""),"",IF(OR(AND(K13<>"",TODAY()-K13>=14),AND(F13<>"",TODAY()-F13>=21)),"Red",IF(OR(AND(K13<>"",TODAY()-K13>=7),AND(C13<>"",C13-TODAY()<=30)),"Yellow","Green"))) | E13: =IF(K13="","",TODAY()-K13) | F13: =IFERROR(1/(1/MAXIFS(Touchpoints!$A:$A,Touchpoints!$B:$B,A13)),"") | G13: =IF(F13="","",TODAY()-F13) | K13: 46139 | L13: M-0012 | M13: none | R13: peter.sanderson@example.com | S13: 12 | T13: yes
A14: Julius Yates | B14: 46018 | C14: =IF(B14="","",EDATE(B14,12*(DATEDIF(B14,TODAY(),"y")+1))) | D14: =IF(AND(K14="",F14=""),"",IF(OR(AND(K14<>"",TODAY()-K14>=14),AND(F14<>"",TODAY()-F14>=21)),"Red",IF(OR(AND(K14<>"",TODAY()-K14>=7),AND(C14<>"",C14-TODAY()<=30)),"Yellow","Green"))) | E14: =IF(K14="","",TODAY()-K14) | F14: =IFERROR(1/(1/MAXIFS(Touchpoints!$A:$A,Touchpoints!$B:$B,A14)),"") | G14: =IF(F14="","",TODAY()-F14) | K14: 46311 | L14: M-0013 | M14: none | R14: julius.yates@example.com | S14: 7 | T14: yes
A15: Hamish Lindqvist | B15: 46033 | C15: =IF(B15="","",EDATE(B15,12*(DATEDIF(B15,TODAY(),"y")+1))) | D15: =IF(AND(K15="",F15=""),"",IF(OR(AND(K15<>"",TODAY()-K15>=14),AND(F15<>"",TODAY()-F15>=21)),"Red",IF(OR(AND(K15<>"",TODAY()-K15>=7),AND(C15<>"",C15-TODAY()<=30)),"Yellow","Green"))) | E15: =IF(K15="","",TODAY()-K15) | F15: =IFERROR(1/(1/MAXIFS(Touchpoints!$A:$A,Touchpoints!$B:$B,A15)),"") | G15: =IF(F15="","",TODAY()-F15) | K15: 46240 | L15: M-0014 | M15: none | R15: hamish.lindqvist@example.com | S15: 29 | T15: yes
A16: Silas Quigley | B16: 46037 | C16: =IF(B16="","",EDATE(B16,12*(DATEDIF(B16,TODAY(),"y")+1))) | D16: =IF(AND(K16="",F16=""),"",IF(OR(AND(K16<>"",TODAY()-K16>=14),AND(F16<>"",TODAY()-F16>=21)),"Red",IF(OR(AND(K16<>"",TODAY()-K16>=7),AND(C16<>"",C16-TODAY()<=30)),"Yellow","Green"))) | E16: =IF(K16="","",TODAY()-K16) | F16: =IFERROR(1/(1/MAXIFS(Touchpoints!$A:$A,Touchpoints!$B:$B,A16)),"") | G16: =IF(F16="","",TODAY()-F16) | K16: 46311 | L16: M-0015 | M16: none | R16: silas.quigley@example.com | S16: 20 | T16: yes
A17: Padraig Fairbanks | B17: 46037 | C17: =IF(B17="","",EDATE(B17,12*(DATEDIF(B17,TODAY(),"y")+1))) | D17: =IF(AND(K17="",F17=""),"",IF(OR(AND(K17<>"",TODAY()-K17>=14),AND(F17<>"",TODAY()-F17>=21)),"Red",IF(OR(AND(K17<>"",TODAY()-K17>=7),AND(C17<>"",C17-TODAY()<=30)),"Yellow","Green"))) | E17: =IF(K17="","",TODAY()-K17) | F17: =IFERROR(1/(1/MAXIFS(Touchpoints!$A:$A,Touchpoints!$B:$B,A17)),"") | G17: =IF(F17="","",TODAY()-F17) | K17: 46311 | L17: M-0016 | M17: none | R17: padraig.fairbanks@example.com | S17: 10 | T17: yes
A18: Franklin Yarrow | B18: 46038 | C18: =IF(B18="","",EDATE(B18,12*(DATEDIF(B18,TODAY(),"y")+1))) | D18: =IF(AND(K18="",F18=""),"",IF(OR(AND(K18<>"",TODAY()-K18>=14),AND(F18<>"",TODAY()-F18>=21)),"Red",IF(OR(AND(K18<>"",TODAY()-K18>=7),AND(C18<>"",C18-TODAY()<=30)),"Yellow","Green"))) | E18: =IF(K18="","",TODAY()-K18) | F18: =IFERROR(1/(1/MAXIFS(Touchpoints!$A:$A,Touchpoints!$B:$B,A18)),"") | G18: =IF(F18="","",TODAY()-F18) | H18: finish the first draft of my book | K18: 46238 | L18: M-0017 | M18: none | R18: franklin.yarrow@example.com | S18: 6 | T18: yes
A19: Stanley Pomeroy | B19: 46038 | C19: =IF(B19="","",EDATE(B19,12*(DATEDIF(B19,TODAY(),"y")+1))) | D19: =IF(AND(K19="",F19=""),"",IF(OR(AND(K19<>"",TODAY()-K19>=14),AND(F19<>"",TODAY()-F19>=21)),"Red",IF(OR(AND(K19<>"",TODAY()-K19>=7),AND(C19<>"",C19-TODAY()<=30)),"Yellow","Green"))) | E19: =IF(K19="","",TODAY()-K19) | F19: =IFERROR(1/(1/MAXIFS(Touchpoints!$A:$A,Touchpoints!$B:$B,A19)),"") | G19: =IF(F19="","",TODAY()-F19) | K19: 46290 | L19: M-0018 | M19: none | R19: stanley.pomeroy@example.com | S19: 35 | T19: yes
A20: Caleb Ashford | B20: 46038 | C20: =IF(B20="","",EDATE(B20,12*(DATEDIF(B20,TODAY(),"y")+1))) | D20: =IF(AND(K20="",F20=""),"",IF(OR(AND(K20<>"",TODAY()-K20>=14),AND(F20<>"",TODAY()-F20>=21)),"Red",IF(OR(AND(K20<>"",TODAY()-K20>=7),AND(C20<>"",C20-TODAY()<=30)),"Yellow","Green"))) | E20: =IF(K20="","",TODAY()-K20) | F20: =IFERROR(1/(1/MAXIFS(Touchpoints!$A:$A,Touchpoints!$B:$B,A20)),"") | G20: =IF(F20="","",TODAY()-F20) | K20: 46271 | L20: M-0019 | M20: none | R20: caleb.ashford@example.com | S20: 3 | T20: yes
A21: Derek Larimore | B21: 46039 | C21: =IF(B21="","",EDATE(B21,12*(DATEDIF(B21,TODAY(),"y")+1))) | D21: =IF(AND(K21="",F21=""),"",IF(OR(AND(K21<>"",TODAY()-K21>=14),AND(F21<>"",TODAY()-F21>=21)),"Red",IF(OR(AND(K21<>"",TODAY()-K21>=7),AND(C21<>"",C21-TODAY()<=30)),"Yellow","Green"))) | E21: =IF(K21="","",TODAY()-K21) | F21: =IFERROR(1/(1/MAXIFS(Touchpoints!$A:$A,Touchpoints!$B:$B,A21)),"") | G21: =IF(F21="","",TODAY()-F21) | K21: 46263 | L21: M-0020 | M21: none | R21: derek.larimore@example.com | S21: 39 | T21: yes
A22: Enzo Ingram | B22: 46039 | C22: =IF(B22="","",EDATE(B22,12*(DATEDIF(B22,TODAY(),"y")+1))) | D22: =IF(AND(K22="",F22=""),"",IF(OR(AND(K22<>"",TODAY()-K22>=14),AND(F22<>"",TODAY()-F22>=21)),"Red",IF(OR(AND(K22<>"",TODAY()-K22>=7),AND(C22<>"",C22-TODAY()<=30)),"Yellow","Green"))) | E22: =IF(K22="","",TODAY()-K22) | F22: =IFERROR(1/(1/MAXIFS(Touchpoints!$A:$A,Touchpoints!$B:$B,A22)),"") | G22: =IF(F22="","",TODAY()-F22) | K22: 46085 | L22: M-0021 | M22: none | R22: enzo.ingram@example.com | S22: 26 | T22: yes
A23: Andrei Upton | B23: 46040 | C23: =IF(B23="","",EDATE(B23,12*(DATEDIF(B23,TODAY(),"y")+1))) | D23: =IF(AND(K23="",F23=""),"",IF(OR(AND(K23<>"",TODAY()-K23>=14),AND(F23<>"",TODAY()-F23>=21)),"Red",IF(OR(AND(K23<>"",TODAY()-K23>=7),AND(C23<>"",C23-TODAY()<=30)),"Yellow","Green"))) | E23: =IF(K23="","",TODAY()-K23) | F23: =IFERROR(1/(1/MAXIFS(Touchpoints!$A:$A,Touchpoints!$B:$B,A23)),"") | G23: =IF(F23="","",TODAY()-F23) | K23: 46278 | L23: M-0022 | M23: none | R23: andrei.upton@example.com | S23: 29 | T23: yes
A24: Anders Zeigler | B24: 46042 | C24: =IF(B24="","",EDATE(B24,12*(DATEDIF(B24,TODAY(),"y")+1))) | D24: =IF(AND(K24="",F24=""),"",IF(OR(AND(K24<>"",TODAY()-K24>=14),AND(F24<>"",TODAY()-F24>=21)),"Red",IF(OR(AND(K24<>"",TODAY()-K24>=7),AND(C24<>"",C24-TODAY()<=30)),"Yellow","Green"))) | E24: =IF(K24="","",TODAY()-K24) | F24: =IFERROR(1/(1/MAXIFS(Touchpoints!$A:$A,Touchpoints!$B:$B,A24)),"") | G24: =IF(F24="","",TODAY()-F24) | K24: 46206 | L24: M-0023 | M24: none | R24: anders.zeigler@example.com | S24: 40 | T24: yes
A25: Duncan Jamison | B25: 46044 | C25: =IF(B25="","",EDATE(B25,12*(DATEDIF(B25,TODAY(),"y")+1))) | D25: =IF(AND(K25="",F25=""),"",IF(OR(AND(K25<>"",TODAY()-K25>=14),AND(F25<>"",TODAY()-F25>=21)),"Red",IF(OR(AND(K25<>"",TODAY()-K25>=7),AND(C25<>"",C25-TODAY()<=30)),"Yellow","Green"))) | E25: =IF(K25="","",TODAY()-K25) | F25: =IFERROR(1/(1/MAXIFS(Touchpoints!$A:$A,Touchpoints!$B:$B,A25)),"") | G25: =IF(F25="","",TODAY()-F25) | H25: launch my coaching offer by December | K25: 46244 | L25: M-0024 | M25: none | R25: duncan.jamison@example.com | S25: 11 | T25: yes
A26: Karl Rowntree | B26: 46045 | C26: =IF(B26="","",EDATE(B26,12*(DATEDIF(B26,TODAY(),"y")+1))) | D26: =IF(AND(K26="",F26=""),"",IF(OR(AND(K26<>"",TODAY()-K26>=14),AND(F26<>"",TODAY()-F26>=21)),"Red",IF(OR(AND(K26<>"",TODAY()-K26>=7),AND(C26<>"",C26-TODAY()<=30)),"Yellow","Green"))) | E26: =IF(K26="","",TODAY()-K26) | F26: =IFERROR(1/(1/MAXIFS(Touchpoints!$A:$A,Touchpoints!$B:$B,A26)),"") | G26: =IF(F26="","",TODAY()-F26) | K26: 46307 | L26: M-0025 | M26: none | R26: karl.rowntree@example.com | S26: 40 | T26: yes
A27: Micah Yardley | B27: 46046 | C27: =IF(B27="","",EDATE(B27,12*(DATEDIF(B27,TODAY(),"y")+1))) | D27: =IF(AND(K27="",F27=""),"",IF(OR(AND(K27<>"",TODAY()-K27>=14),AND(F27<>"",TODAY()-F27>=21)),"Red",IF(OR(AND(K27<>"",TODAY()-K27>=7),AND(C27<>"",C27-TODAY()<=30)),"Yellow","Green"))) | E27: =IF(K27="","",TODAY()-K27) | F27: =IFERROR(1/(1/MAXIFS(Touchpoints!$A:$A,Touchpoints!$B:$B,A27)),"") | G27: =IF(F27="","",TODAY()-F27) | K27: 46311 | L27: M-0026 | M27: none | R27: micah.yardley@example.com | S27: 1 | T27: yes
A28: Rafael Huxley | B28: 46048 | C28: =IF(B28="","",EDATE(B28,12*(DATEDIF(B28,TODAY(),"y")+1))) | D28: =IF(AND(K28="",F28=""),"",IF(OR(AND(K28<>"",TODAY()-K28>=14),AND(F28<>"",TODAY()-F28>=21)),"Red",IF(OR(AND(K28<>"",TODAY()-K28>=7),AND(C28<>"",C28-TODAY()<=30)),"Yellow","Green"))) | E28: =IF(K28="","",TODAY()-K28) | F28: =IFERROR(1/(1/MAXIFS(Touchpoints!$A:$A,Touchpoints!$B:$B,A28)),"") | G28: =IF(F28="","",TODAY()-F28) | K28: 46309 | L28: M-0027 | M28: none | R28: rafael.huxley@example.com | S28: 34 | T28: yes
A29: Xavier Jernigan | B29: 46050 | C29: =IF(B29="","",EDATE(B29,12*(DATEDIF(B29,TODAY(),"y")+1))) | D29: =IF(AND(K29="",F29=""),"",IF(OR(AND(K29<>"",TODAY()-K29>=14),AND(F29<>"",TODAY()-F29>=21)),"Red",IF(OR(AND(K29<>"",TODAY()-K29>=7),AND(C29<>"",C29-TODAY()<=30)),"Yellow","Green"))) | E29: =IF(K29="","",TODAY()-K29) | F29: =IFERROR(1/(1/MAXIFS(Touchpoints!$A:$A,Touchpoints!$B:$B,A29)),"") | G29: =IF(F29="","",TODAY()-F29) | K29: 46302 | L29: M-0028 | M29: none | R29: xavier.jernigan@example.com | S29: 5 | T29: yes
A30: Luigi Winslow | B30: 46057 | C30: =IF(B30="","",EDATE(B30,12*(DATEDIF(B30,TODAY(),"y")+1))) | D30: =IF(AND(K30="",F30=""),"",IF(OR(AND(K30<>"",TODAY()-K30>=14),AND(F30<>"",TODAY()-F30>=21)),"Red",IF(OR(AND(K30<>"",TODAY()-K30>=7),AND(C30<>"",C30-TODAY()<=30)),"Yellow","Green"))) | E30: =IF(K30="","",TODAY()-K30) | F30: =IFERROR(1/(1/MAXIFS(Touchpoints!$A:$A,Touchpoints!$B:$B,A30)),"") | G30: =IF(F30="","",TODAY()-F30) | K30: 46295 | L30: M-0029 | M30: none | R30: luigi.winslow@example.com | S30: 4 | T30: yes
A31: Rowan Ridgeway | B31: 46058 | C31: =IF(B31="","",EDATE(B31,12*(DATEDIF(B31,TODAY(),"y")+1))) | D31: =IF(AND(K31="",F31=""),"",IF(OR(AND(K31<>"",TODAY()-K31>=14),AND(F31<>"",TODAY()-F31>=21)),"Red",IF(OR(AND(K31<>"",TODAY()-K31>=7),AND(C31<>"",C31-TODAY()<=30)),"Yellow","Green"))) | E31: =IF(K31="","",TODAY()-K31) | F31: =IFERROR(1/(1/MAXIFS(Touchpoints!$A:$A,Touchpoints!$B:$B,A31)),"") | G31: =IF(F31="","",TODAY()-F31) | K31: 46266 | L31: M-0030 | M31: none | R31: rowan.ridgeway@example.com | S31: 3 | T31: yes
A32: Silas Ingram | B32: 46059 | C32: =IF(B32="","",EDATE(B32,12*(DATEDIF(B32,TODAY(),"y")+1))) | D32: =IF(AND(K32="",F32=""),"",IF(OR(AND(K32<>"",TODAY()-K32>=14),AND(F32<>"",TODAY()-F32>=21)),"Red",IF(OR(AND(K32<>"",TODAY()-K32>=7),AND(C32<>"",C32-TODAY()<=30)),"Yellow","Green"))) | E32: =IF(K32="","",TODAY()-K32) | F32: =IFERROR(1/(1/MAXIFS(Touchpoints!$A:$A,Touchpoints!$B:$B,A32)),"") | G32: =IF(F32="","",TODAY()-F32) | K32: 46311 | L32: M-0031 | M32: none | R32: silas.ingram@example.com | S32: 13 | T32: yes
A33: Lars Glendower | B33: 45697 | C33: =IF(B33="","",EDATE(B33,12*(DATEDIF(B33,TODAY(),"y")+1))) | D33: =IF(AND(K33="",F33=""),"",IF(OR(AND(K33<>"",TODAY()-K33>=14),AND(F33<>"",TODAY()-F33>=21)),"Red",IF(OR(AND(K33<>"",TODAY()-K33>=7),AND(C33<>"",C33-TODAY()<=30)),"Yellow","Green"))) | E33: =IF(K33="","",TODAY()-K33) | F33: =IFERROR(1/(1/MAXIFS(Touchpoints!$A:$A,Touchpoints!$B:$B,A33)),"") | G33: =IF(F33="","",TODAY()-F33) | K33: 46161 | L33: M-0032 | M33: none | R33: lars.glendower@example.com | S33: 16 | T33: yes
A34: Terrence Lachlan | B34: 46064 | C34: =IF(B34="","",EDATE(B34,12*(DATEDIF(B34,TODAY(),"y")+1))) | D34: =IF(AND(K34="",F34=""),"",IF(OR(AND(K34<>"",TODAY()-K34>=14),AND(F34<>"",TODAY()-F34>=21)),"Red",IF(OR(AND(K34<>"",TODAY()-K34>=7),AND(C34<>"",C34-TODAY()<=30)),"Yellow","Green"))) | E34: =IF(K34="","",TODAY()-K34) | F34: =IFERROR(1/(1/MAXIFS(Touchpoints!$A:$A,Touchpoints!$B:$B,A34)),"") | G34: =IF(F34="","",TODAY()-F34) | J34: Moderator | K34: 46307 | L34: M-0033 | M34: none | R34: terrence.lachlan@example.com | S34: 39 | T34: yes
A35: Ivan Montgomery | B35: 46065 | C35: =IF(B35="","",EDATE(B35,12*(DATEDIF(B35,TODAY(),"y")+1))) | D35: =IF(AND(K35="",F35=""),"",IF(OR(AND(K35<>"",TODAY()-K35>=14),AND(F35<>"",TODAY()-F35>=21)),"Red",IF(OR(AND(K35<>"",TODAY()-K35>=7),AND(C35<>"",C35-TODAY()<=30)),"Yellow","Green"))) | E35: =IF(K35="","",TODAY()-K35) | F35: =IFERROR(1/(1/MAXIFS(Touchpoints!$A:$A,Touchpoints!$B:$B,A35)),"") | G35: =IF(F35="","",TODAY()-F35) | K35: 46308 | L35: M-0034 | M35: none | R35: ivan.montgomery@example.com | S35: 2 | T35: yes
A36: Xavier Ashford | B36: 46069 | C36: =IF(B36="","",EDATE(B36,12*(DATEDIF(B36,TODAY(),"y")+1))) | D36: =IF(AND(K36="",F36=""),"",IF(OR(AND(K36<>"",TODAY()-K36>=14),AND(F36<>"",TODAY()-F36>=21)),"Red",IF(OR(AND(K36<>"",TODAY()-K36>=7),AND(C36<>"",C36-TODAY()<=30)),"Yellow","Green"))) | E36: =IF(K36="","",TODAY()-K36) | F36: =IFERROR(1/(1/MAXIFS(Touchpoints!$A:$A,Touchpoints!$B:$B,A36)),"") | G36: =IF(F36="","",TODAY()-F36) | K36: 46127 | L36: M-0035 | M36: none | R36: xavier.ashford@example.com | S36: 30 | T36: yes
A37: Mateo Calloway | B37: 46070 | C37: =IF(B37="","",EDATE(B37,12*(DATEDIF(B37,TODAY(),"y")+1))) | D37: =IF(AND(K37="",F37=""),"",IF(OR(AND(K37<>"",TODAY()-K37>=14),AND(F37<>"",TODAY()-F37>=21)),"Red",IF(OR(AND(K37<>"",TODAY()-K37>=7),AND(C37<>"",C37-TODAY()<=30)),"Yellow","Green"))) | E37: =IF(K37="","",TODAY()-K37) | F37: =IFERROR(1/(1/MAXIFS(Touchpoints!$A:$A,Touchpoints!$B:$B,A37)),"") | G37: =IF(F37="","",TODAY()-F37) | K37: 46284 | L37: M-0036 | M37: none | R37: mateo.calloway@example.com | S37: 21 | T37: yes
A38: Peter Jamison | B38: 46070 | C38: =IF(B38="","",EDATE(B38,12*(DATEDIF(B38,TODAY(),"y")+1))) | D38: =IF(AND(K38="",F38=""),"",IF(OR(AND(K38<>"",TODAY()-K38>=14),AND(F38<>"",TODAY()-F38>=21)),"Red",IF(OR(AND(K38<>"",TODAY()-K38>=7),AND(C38<>"",C38-TODAY()<=30)),"Yellow","Green"))) | E38: =IF(K38="","",TODAY()-K38) | F38: =IFERROR(1/(1/MAXIFS(Touchpoints!$A:$A,Touchpoints!$B:$B,A38)),"") | G38: =IF(F38="","",TODAY()-F38) | K38: 46296 | L38: M-0037 | M38: none | R38: peter.jamison@example.com | S38: 29 | T38: yes
A39: Levi Pruitt | B39: 46075 | C39: =IF(B39="","",EDATE(B39,12*(DATEDIF(B39,TODAY(),"y")+1))) | D39: =IF(AND(K39="",F39=""),"",IF(OR(AND(K39<>"",TODAY()-K39>=14),AND(F39<>"",TODAY()-F39>=21)),"Red",IF(OR(AND(K39<>"",TODAY()-K39>=7),AND(C39<>"",C39-TODAY()<=30)),"Yellow","Green"))) | E39: =IF(K39="","",TODAY()-K39) | F39: =IFERROR(1/(1/MAXIFS(Touchpoints!$A:$A,Touchpoints!$B:$B,A39)),"") | G39: =IF(F39="","",TODAY()-F39) | K39: 46279 | L39: M-0038 | M39: none | R39: levi.pruitt@example.com | S39: 38 | T39: yes
A40: Padraig Fairview | B40: 46075 | C40: =IF(B40="","",EDATE(B40,12*(DATEDIF(B40,TODAY(),"y")+1))) | D40: =IF(AND(K40="",F40=""),"",IF(OR(AND(K40<>"",TODAY()-K40>=14),AND(F40<>"",TODAY()-F40>=21)),"Red",IF(OR(AND(K40<>"",TODAY()-K40>=7),AND(C40<>"",C40-TODAY()<=30)),"Yellow","Green"))) | E40: =IF(K40="","",TODAY()-K40) | F40: =IFERROR(1/(1/MAXIFS(Touchpoints!$A:$A,Touchpoints!$B:$B,A40)),"") | G40: =IF(F40="","",TODAY()-F40) | H40: land 3 new consulting clients | K40: 46147 | L40: M-0039 | M40: none | R40: padraig.fairview@example.com | S40: 13 | T40: yes
...

Sheet Touchpoints
A1: Date | B1: Member | C1: Type | D1: What was said | E1: Commitment he made | F1: Follow-up date | G1: member_id | H1: channel | I1: direction | J1: draft_id | K1: replied | L1: reply_date

Sheet Weekly pulse
A1: Week of | B1: Member | C1: Active in Skool | D1: Attended call | E1: Did last week's commitment | F1: This week's commitment

Sheet How to use
A1: How this tracker works
A2: 1. Members: one row per member (admins and owner excluded). Names are anonymized placeholders for the demo.
A3: 2. Join date comes from Skool. Renewal date is the next anniversary of the join date and rolls forward each year.
A4: 3. Status turns Red if not active in Skool 14+ days or no contact from you in 21+ days; Yellow if inactive 7 to 13 days or renewal within 30 days; Green otherwise.
A5: 4. Touchpoints: log every DM, call or check-in (pick the member from the dropdown). 'Last contact' on Members fills itself from here.
A6: 5. Weekly pulse: one row per member each Monday.
A7: Northstar Coaching Circle is a fictional demo community. Member names are placeholders; goals are made up.
A9: Re-engagement loop (added for the hackathon test)
A10: channel: 'none' = draft and review only, never sent. During setup, Fo fills in the tester row(s) with a real name and email and sets channel to 'email'; only those rows can receive a real message.
A11: member_id: the loop's ID for each member. IDs ending in 0 or 5 are the hold-back group and are never contacted.
A12: Touchpoints: the loop adds member_id, channel, direction (out/in), draft_id and replies; 'Last contact' still fills from here.
A13: Status history, Drafts, Conversions, Checks, Scorecard and Run log are written by Fo and Claude. Don't edit them by hand.
A14: email, posts, intro_posted: from the member export. Emails here are fictional (example.com). posts = 0 and intro_posted = no means the member never got started.

Sheet Status history
A1: date | B1: member_id | C1: stage

Sheet Drafts
A1: draft_id | B1: date | C1: member_id | D1: name | E1: rule | F1: reason | G1: status | H1: final_text | I1: approved_at | J1: sent_at

Sheet Conversions
A1: date | B1: member_id | C1: type | D1: value

Sheet Checks
A1: date | B1: draft_id | C1: member_id | D1: flag | E1: reason

Sheet Scorecard
A1: date | B1: review_minutes | C1: baseline_minutes | D1: drafts | E1: approved | F1: sent | G1: contacted_moved_up | H1: contacted_total | I1: holdout_moved_up | J1: holdout_total | K1: revenue_attributed | L1: revenue_target | M1: note

Sheet Run log
A1: timestamp | B1: step | C1: agent | D1: status | E1: drafts | F1: checked | G1: sent | H1: note
